django      | 2025-02-18 11:49:46,499 ERROR    Exception inside application: empty range for randrange() (0, 0, 0)
django      | Traceback (most recent call last):
django      |   File "/usr/local/lib/python3.11/site-packages/channels/routing.py", line 48, in __call__
django      |     return await application(scope, receive, send)
django      |            ^^^^^^^^^^^^^^^^^^^^^^^^^^^^^^^^^^^^^^^
django      |   File "/usr/local/lib/python3.11/site-packages/channels/security/websocket.py", line 37, in __call__
django      |     return await self.application(scope, receive, send)
django      |            ^^^^^^^^^^^^^^^^^^^^^^^^^^^^^^^^^^^^^^^^^^^^
django      |   File "/usr/local/lib/python3.11/site-packages/channels/sessions.py", line 44, in __call__
django      |     return await self.inner(dict(scope, cookies=cookies), receive, send)
django      |            ^^^^^^^^^^^^^^^^^^^^^^^^^^^^^^^^^^^^^^^^^^^^^^^^^^^^^^^^^^^^^
django      |   File "/usr/local/lib/python3.11/site-packages/channels/sessions.py", line 261, in __call__
django      |     return await self.inner(wrapper.scope, receive, wrapper.send)
django      |            ^^^^^^^^^^^^^^^^^^^^^^^^^^^^^^^^^^^^^^^^^^^^^^^^^^^^^^
django      |   File "/usr/local/lib/python3.11/site-packages/channels/auth.py", line 185, in __call__
django      |     return await super().__call__(scope, receive, send)
django      |            ^^^^^^^^^^^^^^^^^^^^^^^^^^^^^^^^^^^^^^^^^^^^
django      |   File "/usr/local/lib/python3.11/site-packages/channels/middleware.py", line 24, in __call__
django      |     return await self.inner(scope, receive, send)
django      |            ^^^^^^^^^^^^^^^^^^^^^^^^^^^^^^^^^^^^^^
django      |   File "/usr/local/lib/python3.11/site-packages/channels/routing.py", line 118, in __call__
django      |     return await application(
django      |            ^^^^^^^^^^^^^^^^^^
django      |   File "/usr/local/lib/python3.11/site-packages/channels/consumer.py", line 95, in app
django      |     return await consumer(scope, receive, send)
django      |            ^^^^^^^^^^^^^^^^^^^^^^^^^^^^^^^^^^^^
django      |   File "/usr/local/lib/python3.11/site-packages/channels/consumer.py", line 58, in __call__
django      |     await await_many_dispatch(
django      |   File "/usr/local/lib/python3.11/site-packages/channels/utils.py", line 50, in await_many_dispatch
django      |     await dispatch(result)
django      |   File "/usr/local/lib/python3.11/site-packages/asgiref/sync.py", line 468, in __call__
django      |     ret = await asyncio.shield(exec_coro)
django      |           ^^^^^^^^^^^^^^^^^^^^^^^^^^^^^^^
django      |   File "/usr/local/lib/python3.11/concurrent/futures/thread.py", line 58, in run
django      |     result = self.fn(*self.args, **self.kwargs)
django      |              ^^^^^^^^^^^^^^^^^^^^^^^^^^^^^^^^^^
django      |   File "/usr/local/lib/python3.11/site-packages/channels/db.py", line 13, in thread_handler
django      |     return super().thread_handler(loop, *args, **kwargs)
django      |            ^^^^^^^^^^^^^^^^^^^^^^^^^^^^^^^^^^^^^^^^^^^^^
django      |   File "/usr/local/lib/python3.11/site-packages/asgiref/sync.py", line 522, in thread_handler
django      |     return func(*args, **kwargs)
django      |            ^^^^^^^^^^^^^^^^^^^^^
django      |   File "/usr/local/lib/python3.11/site-packages/channels/consumer.py", line 126, in dispatch
django      |     handler(message)
django      |   File "/usr/local/lib/python3.11/site-packages/channels/generic/websocket.py", line 64, in websocket_receive
django      |     self.receive(text_data=message["text"])
django      |   File "/project/backend_tour_app/consumers.py", line 49, in receive
django      |     response = self.runGame()
django      |                ^^^^^^^^^^^^^^
django      |   File "/project/backend_tour_app/consumers.py", line 94, in runGame
django      |     player2 = players_in_phase[random.randrange(0, len(players_in_phase))]
django      |                                ^^^^^^^^^^^^^^^^^^^^^^^^^^^^^^^^^^^^^^^^^^
django      |   File "/usr/local/lib/python3.11/random.py", line 345, in randrange
django      |     raise ValueError("empty range for randrange() (%d, %d, %d)" % (istart, istop, width))
django      | ValueError: empty range for randrange() (0, 0, 0)
nginx       | 172.18.0.1 - - [18/Feb/2025:10:49:46 +0000] "GET /ws/tournament/ HTTP/1.1" 101 128 "-" "Mozilla/5.0 (X11; Linux x86_64) AppleWebKit/537.36 (KHTML, like Gecko) Chrome/131.0.0.0 Safari/537.36"
nginx       | 2025/02/18 10:49:46 [error] 7#7: *428 recv() failed (104: Connection reset by peer) while proxying upgraded connection, client: 172.18.0.1, server: localhost, request: "GET /ws/tournament/ HTTP/1.1", upstream: "http://172.18.0.3:8000/ws/tournament/", host: "localhost"



after any game actually
cannot throw a new tournement just after one without reloading

 2025-02-18 17:46:17,232 INFO     ['172.18.0.5', 56524]
django      | 2025-02-18 17:46:17,253 ERROR    Task exception was never retrieved
django      | future: <Task finished name='Task-6953' coro=<PongConsumer.loop() done, defined at /project/remotePlayer_app/consumers.py:169> exception=KeyError('y')>
django      | Traceback (most recent call last):
django      |   File "/project/remotePlayer_app/consumers.py", line 174, in loop
django      |     await self.calculBallMovement(matchId)
django      |   File "/project/remotePlayer_app/consumers.py", line 218, in calculBallMovement
django      |     await self.ballWallCollision(m)
django      |   File "/project/remotePlayer_app/consumers.py", line 236, in ballWallCollision
django      |     elif (m["ball"]["y"] + m["ball"]["gravity"] >= m["playerOne"]["y"]
django      |                                                   ~~~~~~~~~~~~~~^^^^^
django      | KeyError: 'y'
